Workbook

Sheet Test cases
A1: ID | B1: Area | C1: IR objective | D1: Test case | E1: Steps | F1: Expected result | G1: How tested | H1: Evidence | I1: Actual result | J1: Status | K1: Date tested | L1: Notes
A2: TC-01 | B2: Academic skills | C2: 1 | D2: Grades turn modules into skills | E2: Student opens My Profile > Modules, sets A for Python Programming, saves | F2: The module turns into its skills: the skill count goes from 0 to 3 (Python, Programming, Debugging) and the grade is saved | G2: Playwright E2E | H2: Playwright 22 Oct (13 passed, docs/evidence/e2e/run_2026-10-22.txt): 1-student.spec.js; screenshot docs/evidence/e2e/TC-01_grade_to_skills.png | I2: Python Programming at A, saved: "3 skills found in your modules" (Python, Programming, Debugging) | J2: Pass | K2: 22 Oct 2026
A3: TC-02 | B3: Academic skills | C3: 1 | D3: Only pass grades are accepted | E3: Send a grade below C (e.g. D) for a module | F3: Refused with 'Grade must be one of A, A-, B+, B, B-, C+ or C' | G3: Automated | H3: pytest 21 Oct (137 passed): test_grades.py::test_only_pass_grades_are_accepted | I3: As expected | J3: Pass | K3: 21 Oct 2026
A4: TC-03 | B4: Academic skills | C4: 1 | D4: Changing programme asks before removing grades | E4: Student with grades changes programme | F4: Asked to confirm; grades removed only after confirming | G4: Automated | H4: pytest 21 Oct (137 passed): test_grades.py::test_changing_programme_removes_grades_only_after_confirming | I4: As expected | J4: Pass | K4: 21 Oct 2026
A5: TC-04 | B5: Academic skills | C5: 1 | D5: Career office reviews module skills | E5: Admin opens a module, removes a skill, adds one, marks reviewed | F5: Changes saved and recorded; students get the reviewed skills | G5: Automated | H5: pytest 21 Oct (137 passed): test_extraction_records.py::test_module_extraction_and_career_office_changes | I5: As expected | J5: Pass | K5: 21 Oct 2026
A6: TC-05 | B6: Academic skills | C6: 1 | D6: Module skill extraction quality | E6: Evaluation step 3 + prompt v2 on 30 new modules (3 labellers, rules set beforehand) | F6: F1 passes the pre-set bar | G6: Evaluation | H6: F1 0.746 (v1 0.581); docs/evidence/module_prompt_v2 | I6: As expected | J6: Pass | K6: 21 Oct 2026
A7: TC-06 | B7: Academic skills | C7: 1 | D7: Job ad skill extraction quality | E7: Evaluation step 2: LLM extractor vs spaCy baseline on 30 ads | F7: LLM clearly better than the IR's spaCy approach | G7: Evaluation | H7: F1 0.695 vs 0.250 (+0.445, CI +0.369 to +0.521); docs/evidence/job_skill_extraction | I7: As expected | J7: Pass | K7: 21 Oct 2026
A8: TC-07 | B8: Profile evidence | C8: 1 | D8: Experience skills only from her own words | E8: Student adds an internship; AI suggests skills | F8: Only skills quoted from her description are kept | G8: Automated | H8: pytest 21 Oct (137 passed): test_more_evidence.py::test_suggest_keeps_only_skills_in_her_words | I8: As expected | J8: Pass | K8: 21 Oct 2026
A9: TC-08 | B9: Profile evidence | C9: 1 | D9: Experience reaches every part of SkillMap | E9: Add work + club experience, apply for a job | F9: Skills in the profile, employer view, chatbot CV points, Download my data, and removed on delete | G9: Automated | H9: pytest 21 Oct (137 passed): test_more_evidence.py::test_experience_reaches_profile_employer_chatbot_export_and_delete | I9: As expected | J9: Pass | K9: 21 Oct 2026
A10: TC-09 | B10: Profile evidence | C10: 1 | D10: GitHub connect and import | E10: Student connects GitHub, imports a repository, disconnects | F10: Repositories listed; import needs a connected account; typed links ignored | G10: Automated | H10: pytest 21 Oct (137 passed): test_github_connect.py::test_connect_check_repos_and_disconnect, test_import_needs_a_connected_account_and_typed_link_is_ignored | I10: As expected | J10: Pass | K10: 21 Oct 2026
A11: TC-10 | B11: Profile evidence | C11: 1 | D11: Profile checklist | E11: Student with modules and a project opens My Profile | F11: 'Your profile · 2 of 5 done'; the checklist links to the missing items; hidden when all 5 are done | G11: Playwright E2E | H11: Playwright 22 Oct (13 passed, docs/evidence/e2e/run_2026-10-22.txt): 1-student.spec.js; screenshot docs/evidence/e2e/TC-10_profile_checklist.png | I11: "Your profile · 1 of 5 done"; the checklist ticks Modules and offers Projects, Experience, Certificates, About you | J11: Pass | K11: 22 Oct 2026
A12: TC-11 | B12: Job recommendation | C12: 2 | D12: Job Matches lists jobs for her skills | E12: Student with grades opens Job Matches | F12: Jobs ordered by match, each with matched/required counts | G12: Playwright E2E | H12: Playwright 22 Oct (13 passed, docs/evidence/e2e/run_2026-10-22.txt): 1-student.spec.js; screenshot docs/evidence/e2e/TC-11_job_matches.png | I12: Job Matches lists the 3 open jobs with "1/3 required" or "0/3 required" | J12: Pass | K12: 22 Oct 2026
A13: TC-12 | B13: Job recommendation | C13: 2 | D13: Ranking better than a keyword baseline | E13: Evaluation step 4: 10 programme profiles, 3 judges, nDCG@10 | F13: SkillMap beats keyword matching (pre-set rule) | G13: Evaluation | H13: nDCG@10 0.796 vs 0.526 (CI +0.213 to +0.323); her spot-check 26/27; docs/evidence/ranking | I13: As expected | J13: Pass | K13: 21 Oct 2026
... A37: TC-36 | B37: Employer | C37: - | D37: Post a job: skills read, checked, published | E37: Employer writes an ad, checks the skills, publishes | F37: Skills saved; what the employer changed is recorded | G37: Automated | H37: pytest 21 Oct (137 passed): test_extraction_records.py::test_employer_read_then_publish_records_their_changes | I37: As expected | J37: Pass | K37: 21 Oct 2026
A38: TC-37 | B38: Employer | C38: - | D38: Decision date set and moved once | E38: Post with 'Decide by'; move it twice; try to move it after the date has passed | F38: Set; moved once, by up to 2 weeks, with a reason; second move refused; moving after the date has passed refused | G38: Automated | H38: pytest 26 Oct (184 passed): docs/evidence/tests/pytest_26oct.txt: test_transparency.py::test_decision_date_is_set_when_posting_and_moved_once, test_decision_date_cannot_be_moved_once_it_has_passed | I38: As expected | J38: Pass | K38: 26 Oct 2026 | L38: 26 Oct: the 'only before it passes' rule added (her review: a limit on delays)
A39: TC-38 | B39: Employer | C39: - | D39: Shortlist, undo, reject, correct | E39: Change an applicant's status several times | F39: Each change recorded; Undo restores the previous status | G39: Automated + Playwright E2E | H39: pytest 21 Oct (137 passed): test_applications.py::test_shortlist_back_and_again_then_reject_then_correct, test_undo_restores_the_previous_status_from_history; Playwright 22 Oct (13 passed, docs/evidence/e2e/run_2026-10-22.txt): 2-employer.spec.js; screenshot docs/evidence/e2e/TC-38_student_sees_shortlisted.png | I39: As expected | J39: Pass | K39: 22 Oct 2026
A40: TC-39 | B40: Employer | C40: - | D40: Not selected with a reason | E40: Reject with 'missing skills' | F40: Student sees the reason and her own missing skills | G40: Automated | H40: pytest 21 Oct (137 passed): test_transparency.py::test_not_selected_with_a_reason_the_student_sees | I40: As expected | J40: Pass | K40: 21 Oct 2026
A41: TC-40 | B41: Employer | C41: - | D41: Several Not selected at once | E41: Tick several, one of them another employer's | F41: All or nothing: refused, nothing changed | G41: Automated | H41: pytest 21 Oct (137 passed): test_transparency.py::test_several_at_once_all_or_nothing | I41: As expected | J41: Pass | K41: 21 Oct 2026
A42: TC-41 | B42: Employer | C42: - | D42: Several Shortlisted at once | E42: Tick 3 (one already Accepted), Shortlist | F42: Only the 2 at Applied move; contact details then shown | G42: Automated | H42: pytest 21 Oct (137 passed): test_transparency.py::test_shortlist_several_only_moves_those_at_applied | I42: As expected | J42: Pass | K42: 21 Oct 2026
A43: TC-42 | B43: Employer | C43: - | D43: Contact details only after shortlisting | E43: Open an applicant before and after shortlisting | F43: Email and phone hidden, then shown | G43: Automated + Playwright E2E | H43: pytest 21 Oct (137 passed): test_invitations.py::test_contact_details_only_after_shortlisting; Playwright 22 Oct (13 passed, docs/evidence/e2e/run_2026-10-22.txt): 2-employer.spec.js; screenshot docs/evidence/e2e/TC-42_shortlisted_contact.png | I43: As expected | J43: Pass | K43: 22 Oct 2026
A44: TC-43 | B44: Employer | C44: - | D44: Invite graduates who fit | E44: Invite a visible graduate; invite again | F44: Student sees the invitation; only once | G44: Automated | H44: pytest 26 Oct (184 passed): docs/evidence/tests/pytest_26oct.txt: test_invitations.py::test_invite_flow, test_invite_only_once_even_after_not_interested | I44: As expected | J44: Pass | K44: 26 Oct 2026
A45: TC-44 | B45: Employer | C45: - | D45: After applying, a job asks for less, not more | E45: Someone applied; employer adds a required skill, then removes one | F45: Adding refused with 'Post a new job'; removing allowed; student told what was dropped | G45: Automated | H45: pytest 21 Oct (137 passed): test_edit_job.py::test_edit_changes_skills_and_keeps_locked_fields, test_after_applying_the_job_cant_ask_for_more_qualification_or_languages | I45: As expected | J45: Pass | K45: 21 Oct 2026
A46: TC-45 | B46: Employer | C46: - | D46: Edit and application at the same moment | E46: Save a stricter edit while a student applies, in both orders | F46: Application first: edit refused. Edit first: application made under the new ad (row lock) | G46: Automated | H46: pytest 22 Oct (140 passed): test_edit_job.py::test_real_endpoints_application_first_then_a_stricter_edit_is_refused, test_real_endpoints_edit_first_then_the_application_is_made_under_the_new_ad (both fail without the lock) | I46: As expected | J46: Pass | K46: 21 Oct 2026
A47: TC-46 | B47: Employer | C47: - | D47: Closing a job needs a reason | E47: Close a job with applicants waiting | F47: Reason required; everyone waiting is told | G47: Automated | H47: pytest 21 Oct (137 passed): test_applications.py::test_closing_needs_a_reason_and_tells_everyone_waiting | I47: As expected | J47: Pass | K47: 21 Oct 2026
A48: TC-47 | B48: Employer | C48: - | D48: Reply record shown to students | E48: Employer decides on time on 3 jobs | F48: Students see 'replied on time N of M' | G48: Automated | H48: pytest 21 Oct (137 passed): test_transparency.py::test_employer_record_of_deciding_on_time | I48: As expected | J48: Pass | K48: 21 Oct 2026
A49: TC-48 | B49: Admin | C49: - | D49: Approve an employer | E49: Admin approves a waiting employer | F49: Employer leaves 'waiting' and can post | G49: Automated + Playwright E2E | H49: pytest 21 Oct (137 passed): test_admin.py::test_approve_moves_employer_out_of_waiting; Playwright 22 Oct (13 passed, docs/evidence/e2e/run_2026-10-22.txt): 3-admin.spec.js; screenshot docs/evidence/e2e/TC-48_employer_approved.png | I49: As expected | J49: Pass | K49: 22 Oct 2026
A50: TC-49 | B50: Admin | C50: - | D50: Deactivate an account | E50: Deactivate with and without a reason; deactivate yourself | F50: Reason required; can't deactivate yourself; old login stops working | G50: Automated | H50: pytest 21 Oct (137 passed): test_admin.py (2 tests), test_auth.py::test_deactivated_account_old_token_stops_working | I50: As expected | J50: Pass | K50: 21 Oct 2026
... A54: TC-53 | B54: Accounts | C54: - | D54: Forgot password | E54: Request a code, enter it, set a new password | F54: Code emailed; new password works; old one doesn't | G54: Manual | H54: docs/evidence/manual/TC-53_1 to TC-53_8 (reset page, code email, code verified, password changed, old password refused, new password signs in, password-changed email) | I54: Code arrived in Gmail within a minute, naming the account (tc53test), 15 minutes, single use. Code verified, new password set, "Password changed" message. Old password refused ("Invalid credentials", account not revealed); new password signs in. A "password was changed" email followed, with the time and "other devices have been signed out". Real Gmail delivery (SMTP), test account weilinglow0926+tc53@gmail.com. | J54: Pass | K54: 24 Oct 2026
A55: TC-54 | B55: Privacy | C55: - | D55: Each role reaches only its own pages | E55: Student, employer and admin call each other's pages | F55: Refused (403) | G55: Automated + Playwright E2E | H55: pytest 21 Oct (137 passed): test_auth.py::test_role_checks; Playwright 22 Oct (13 passed, docs/evidence/e2e/run_2026-10-22.txt): 4-access.spec.js; screenshot docs/evidence/e2e/TC-54_student_sent_to_dashboard.png | I55: As expected | J55: Pass | K55: 22 Oct 2026 | L55: In the browser, a student sent to her Dashboard is told "That page is for employers / the career office" (added 22 Oct).
A56: TC-55 | B56: Privacy | C56: - | D56: No one reaches another person's records | E56: Another employer opens my jobs or applicants; a student opens another's applications | F56: Refused (404) | G56: Automated | H56: pytest 21 Oct (137 passed): test_permissions.py (2 tests) | I56: As expected | J56: Pass | K56: 21 Oct 2026
A57: TC-56 | B57: Privacy | C57: - | D57: Grades, languages and CGPA only when she allows | E57: Switch each off and on; view as employer | F57: Shown only when switched on | G57: Automated | H57: pytest 21 Oct (137 passed): test_permissions.py::test_grades_follow_the_students_switch, test_more_evidence.py::test_languages_and_cgpa_only_when_she_allows | I57: As expected | J57: Pass | K57: 21 Oct 2026
A58: TC-57 | B58: Privacy | C58: - | D58: Download my data | E58: Student downloads her data | F58: Every field of her rows included | G58: Automated | H58: pytest 21 Oct (137 passed): test_personal_data.py::test_download_has_every_field_of_my_rows | I58: As expected | J58: Pass | K58: 21 Oct 2026
A59: TC-58 | B59: Privacy | C59: - | D59: Delete my account | E59: Student deletes her account (and retry after a failure) | F59: All her data removed; nothing deleted if chat history can't be reached | G59: Automated | H59: pytest 21 Oct (137 passed): test_delete_account.py (3 tests), test_audit_fixes.py::test_delete_can_be_retried_after_postgres_fails | I59: As expected | J59: Pass | K59: 21 Oct 2026
A60: TC-59 | B60: Privacy | C60: - | D60: Updated privacy notice | E60: Student on the 14 Oct notice signs in | F60: Pop-up says what changed; agreeing records the 21 Oct version | G60: Automated | H60: pytest 21 Oct (137 passed): test_more_evidence.py::test_someone_on_the_old_notice_can_agree_to_the_new_one | I60: As expected | J60: Pass | K60: 21 Oct 2026
A61: TC-60 | B61: Install and reliability | C61: - | D61: Fresh install | E61: Start the API on an empty database, run the data migrations | F61: Starts; programmes, modules and intakes present | G61: Automated | H61: pytest 21 Oct (137 passed): test_install.py (3 tests) | I61: As expected | J61: Pass | K61: 21 Oct 2026
A62: TC-61 | B62: Install and reliability | C62: - | D62: Migrations safe to repeat; outdated database named | E62: Run every migration twice; start with one migration missing | F62: No errors; start-up names the missing migration | G62: Automated | H62: pytest 21 Oct (137 passed): test_install.py::test_every_migration_is_safe_to_run_again, test_audit_fixes.py::test_a_database_one_migration_behind_is_named_then_upgraded | I62: As expected | J62: Pass | K62: 21 Oct 2026
A63: TC-62 | B63: Install and reliability | C63: - | D63: MongoDB down | E63: Stop MongoDB, use the app | F63: Everything works; records reported 'not saved' | G63: Automated | H63: pytest 21 Oct (137 passed): test_extraction_records.py::test_mongodb_down_never_blocks_and_pauses_retries | I63: As expected | J63: Pass | K63: 21 Oct 2026
A64: TC-63 | B64: Install and reliability | C64: - | D64: GitHub down | E64: GitHub unreachable while linking a project | F64: No stale badge shown | G64: Automated | H64: pytest 21 Oct (137 passed): test_github_connect.py::test_github_down_never_shows_an_old_badge_on_a_new_link | I64: As expected | J64: Pass | K64: 21 Oct 2026
A65: TC-64 | B65: Install and reliability | C65: - | D65: Skill reader down while posting | E65: AI unavailable when reading an ad | F65: Clear message; employer can add skills by hand | G65: Manual | H65: docs/evidence/manual/TC-64_1 (reader down: message and new heading), TC-64_2 (published with typed skills); backend/tests/test_extraction_records.py::test_reader_down_says_so_quickly_instead_of_no_skills | I65: Backend started with a wrong GROQ_API_KEY. Read the skills: "SkillMap couldn't read the skills just now. Add them yourself below, or read the skills again in a few minutes" at the top of the skills, heading "Add the skills students are matched on". 3 required + 1 nice-to-have typed by hand; published and live. Found and fixed first (24 Oct): it used to wait 45 s and show no skills and no message; now about 9 s. | J65: Pass | K65: 24 Oct 2026
A66: TC-65 | B66: Non-functional | C66: - | D66: Security: known library holes | E66: Run pip-audit (backend) and npm audit (frontend) | F66: No high or critical issues left unexplained | G66: Tool: npm audit + pip-audit | H66: docs/evidence/security/: npm_audit_2026-10-22_before/after.txt, pip_audit_2026-10-22_before/after.txt | I66: Before: frontend 3 high, backend 58 advisories in 6 packages. After: 0 and 0 (upgrades; python-jose replaced by PyJWT). 140 pytest + 13 browser tests pass after the changes | J66: Pass | K66: 22 Oct 2026
...

Sheet Summary
A1: SkillMap system testing — summary
A2: Counts update from the Status column of 'Test cases'.
A4: Area | B4: Total | C4: Pass | D4: Fail | E4: Not run
A5: Academic skills | B5: =COUNTIF('Test cases'!$B$2:$B$100,A5) -> 6 | C5: =COUNTIFS('Test cases'!$B$2:$B$100,$A5,'Test cases'!$J$2:$J$100,"Pass") -> 6 | D5: =COUNTIFS('Test cases'!$B$2:$B$100,$A5,'Test cases'!$J$2:$J$100,"Fail") -> 0 | E5: =COUNTIFS('Test cases'!$B$2:$B$100,$A5,'Test cases'!$J$2:$J$100,"Not run") -> 0
A6: Profile evidence | B6: =COUNTIF('Test cases'!$B$2:$B$100,A6) -> 4 | C6: =COUNTIFS('Test cases'!$B$2:$B$100,$A6,'Test cases'!$J$2:$J$100,"Pass") -> 4 | D6: =COUNTIFS('Test cases'!$B$2:$B$100,$A6,'Test cases'!$J$2:$J$100,"Fail") -> 0 | E6: =COUNTIFS('Test cases'!$B$2:$B$100,$A6,'Test cases'!$J$2:$J$100,"Not run") -> 0
A7: Job recommendation | B7: =COUNTIF('Test cases'!$B$2:$B$100,A7) -> 5 | C7: =COUNTIFS('Test cases'!$B$2:$B$100,$A7,'Test cases'!$J$2:$J$100,"Pass") -> 5 | D7: =COUNTIFS('Test cases'!$B$2:$B$100,$A7,'Test cases'!$J$2:$J$100,"Fail") -> 0 | E7: =COUNTIFS('Test cases'!$B$2:$B$100,$A7,'Test cases'!$J$2:$J$100,"Not run") -> 0
A8: Skill gap | B8: =COUNTIF('Test cases'!$B$2:$B$100,A8) -> 6 | C8: =COUNTIFS('Test cases'!$B$2:$B$100,$A8,'Test cases'!$J$2:$J$100,"Pass") -> 6 | D8: =COUNTIFS('Test cases'!$B$2:$B$100,$A8,'Test cases'!$J$2:$J$100,"Fail") -> 0 | E8: =COUNTIFS('Test cases'!$B$2:$B$100,$A8,'Test cases'!$J$2:$J$100,"Not run") -> 0
A9: AI assistant | B9: =COUNTIF('Test cases'!$B$2:$B$100,A9) -> 6 | C9: =COUNTIFS('Test cases'!$B$2:$B$100,$A9,'Test cases'!$J$2:$J$100,"Pass") -> 6 | D9: =COUNTIFS('Test cases'!$B$2:$B$100,$A9,'Test cases'!$J$2:$J$100,"Fail") -> 0 | E9: =COUNTIFS('Test cases'!$B$2:$B$100,$A9,'Test cases'!$J$2:$J$100,"Not run") -> 0
A10: Applications | B10: =COUNTIF('Test cases'!$B$2:$B$100,A10) -> 7 | C10: =COUNTIFS('Test cases'!$B$2:$B$100,$A10,'Test cases'!$J$2:$J$100,"Pass") -> 7 | D10: =COUNTIFS('Test cases'!$B$2:$B$100,$A10,'Test cases'!$J$2:$J$100,"Fail") -> 0 | E10: =COUNTIFS('Test cases'!$B$2:$B$100,$A10,'Test cases'!$J$2:$J$100,"Not run") -> 0
A11: Employer | B11: =COUNTIF('Test cases'!$B$2:$B$100,A11) -> 18 | C11: =COUNTIFS('Test cases'!$B$2:$B$100,$A11,'Test cases'!$J$2:$J$100,"Pass") -> 18 | D11: =COUNTIFS('Test cases'!$B$2:$B$100,$A11,'Test cases'!$J$2:$J$100,"Fail") -> 0 | E11: =COUNTIFS('Test cases'!$B$2:$B$100,$A11,'Test cases'!$J$2:$J$100,"Not run") -> 0
A12: Admin | B12: =COUNTIF('Test cases'!$B$2:$B$100,A12) -> 3 | C12: =COUNTIFS('Test cases'!$B$2:$B$100,$A12,'Test cases'!$J$2:$J$100,"Pass") -> 3 | D12: =COUNTIFS('Test cases'!$B$2:$B$100,$A12,'Test cases'!$J$2:$J$100,"Fail") -> 0 | E12: =COUNTIFS('Test cases'!$B$2:$B$100,$A12,'Test cases'!$J$2:$J$100,"Not run") -> 0
A13: Accounts | B13: =COUNTIF('Test cases'!$B$2:$B$100,A13) -> 3 | C13: =COUNTIFS('Test cases'!$B$2:$B$100,$A13,'Test cases'!$J$2:$J$100,"Pass") -> 3 | D13: =COUNTIFS('Test cases'!$B$2:$B$100,$A13,'Test cases'!$J$2:$J$100,"Fail") -> 0 | E13: =COUNTIFS('Test cases'!$B$2:$B$100,$A13,'Test cases'!$J$2:$J$100,"Not run") -> 0
A14: Privacy | B14: =COUNTIF('Test cases'!$B$2:$B$100,A14) -> 6 | C14: =COUNTIFS('Test cases'!$B$2:$B$100,$A14,'Test cases'!$J$2:$J$100,"Pass") -> 6 | D14: =COUNTIFS('Test cases'!$B$2:$B$100,$A14,'Test cases'!$J$2:$J$100,"Fail") -> 0 | E14: =COUNTIFS('Test cases'!$B$2:$B$100,$A14,'Test cases'!$J$2:$J$100,"Not run") -> 0
A15: Install and reliability | B15: =COUNTIF('Test cases'!$B$2:$B$100,A15) -> 6 | C15: =COUNTIFS('Test cases'!$B$2:$B$100,$A15,'Test cases'!$J$2:$J$100,"Pass") -> 6 | D15: =COUNTIFS('Test cases'!$B$2:$B$100,$A15,'Test cases'!$J$2:$J$100,"Fail") -> 0 | E15: =COUNTIFS('Test cases'!$B$2:$B$100,$A15,'Test cases'!$J$2:$J$100,"Not run") -> 0
A16: Non-functional | B16: =COUNTIF('Test cases'!$B$2:$B$100,A16) -> 4 | C16: =COUNTIFS('Test cases'!$B$2:$B$100,$A16,'Test cases'!$J$2:$J$100,"Pass") -> 3 | D16: =COUNTIFS('Test cases'!$B$2:$B$100,$A16,'Test cases'!$J$2:$J$100,"Fail") -> 0 | E16: =COUNTIFS('Test cases'!$B$2:$B$100,$A16,'Test cases'!$J$2:$J$100,"Not run") -> 1
A17: Total | B17: =SUM(B5:B16) -> 74 | C17: =SUM(C5:C16) -> 73 | D17: =SUM(D5:D16) -> 0 | E17: =SUM(E5:E16) -> 1
A19: By IR objective
A20: 1. Academic skill extraction | B20: =COUNTIF('Test cases'!$C$2:$C$100,"1") -> 10 | C20: =COUNTIFS('Test cases'!$C$2:$C$100,"1",'Test cases'!$J$2:$J$100,"Pass") -> 10
A21: 2. Job recommendation | B21: =COUNTIF('Test cases'!$C$2:$C$100,"2") -> 12 | C21: =COUNTIFS('Test cases'!$C$2:$C$100,"2",'Test cases'!$J$2:$J$100,"Pass") -> 12
A22: 3. Explainable skill gap | B22: =COUNTIF('Test cases'!$C$2:$C$100,"3") -> 6 | C22: =COUNTIFS('Test cases'!$C$2:$C$100,"3",'Test cases'!$J$2:$J$100,"Pass") -> 6
A23: 4. AI chatbot | B23: =COUNTIF('Test cases'!$C$2:$C$100,"4") -> 7 | C23: =COUNTIFS('Test cases'!$C$2:$C$100,"4",'Test cases'!$J$2:$J$100,"Pass") -> 7

Sheet How to use
A1: How to use this sheet
A2: Each row is one system test: what you do (Steps) and what should happen (Expected result).
A3: Fill in only these columns as you test: Actual result, Status (Pass / Fail / Not run, from the list), Date tested, Notes.
A4: Automated rows: the whole suite was last run on 26 Oct 2026 on Windows: 184 passed (docs/evidence/tests/pytest_26oct.txt), so rows with an earlier date also passed then. Re-run pytest after any change and update the date.
A5: Evaluation rows come from the evaluation runs (docs/evidence/ and MongoDB evaluation_runs).
A6: 'Playwright E2E' rows are run by the browser tests (docs/testing/e2e.md; last run 26 Oct 2026: 18 passed in Chromium, docs/evidence/e2e/results.json); 'Manual' rows by hand; 'Tool' rows with the named tool.
A7: If a test fails: set Status to Fail, write what happened in Actual result, and note the fix or bug in Notes.
A8: Example of a filled row: TC-01 · Actual: 'Python shown with Module: Python Programming (A)' · Status: Pass · Date: 23 Oct 2026.
